Workbook

Sheet 00_Task1
A1: PROJECT 1 — MONTHLY SALES MIS REPORT
A2: Role | B2: You are the MIS Analyst for a retail company.
A3: Objective | B3: Prepare a reliable monthly sales MIS from raw transaction and master data.
A4: Current task | B4: TASK 1 — Raw Data Inspection & Data Quality Check
A5: Important | B5: Do NOT clean or correct the data yet. First identify and document the issues.
A7: Check | B7: What to look for
A8: 1. Duplicate Invoice IDs | B8: Invoice_ID appearing more than once
A9: 2. Missing Employee IDs | B9: Blank Employee_ID cells
A10: 3. Invalid Employee IDs | B10: Employee_ID not present in Employee_Master
A11: 4. Missing Product IDs | B11: Blank Product_ID cells
A12: 5. Invalid Product IDs | B12: Product_ID not present in Product_Master
A13: 6. Missing Branch IDs | B13: Blank Branch_ID cells
A14: 7. Invalid Branch IDs | B14: Branch_ID not present in Branch_Master
... A22: Next step | B22: After you finish Task 1, tell me what issues you found. I will review your findings before we move to cleaning.

Sheet 01_Sales_Data
A1: Date | B1: Invoice_ID | C1: Employee_ID | D1: Product_ID | E1: Branch_ID | F1: Quantity | G1: Sales_Amount
A2: 46199 | B2: INV100001 | C2: E009 | D2: P002 | E2: B005 | F2: 1 | G2: 279
A3: 46140 | B3: INV100002 | C3: E004 | D3: P009 | E3: B002 | F3: 9 | G3: 3426.25
A4: 46196 | B4: INV100003 | C4: E009 | D4: P007 | E4: B005 | F4: 10 | G4: 2996.51
A5: 46113 | B5: INV100004 | C5: E003 | D5: P012 | E5: B002 | F5: 5 | G5: 1128.54
A6: 46156 | B6: INV100005 | C6: E002 | D6: P002 | E6: B001 | F6: 6 | G6: 1509.15
A7: 46190 | B7: INV100006 | C7: E005 | D7: P001 | E7: B003 | F7: 9 | G7: 3723.38
A8: 46161 | B8: INV100007 | C8: E002 | D8: P009 | E8: B001 | F8: 11 | G8: 3971.59
A9: 46159 | B9: INV100008 | C9: E010 | D9: P004 | E9: B005 | F9: 1 | G9: 147.3
A10: 46150 | B10: INV100009 | C10: E002 | D10: P004 | E10: B004 | F10: 5 | G10: 756.47
A11: 46159 | B11: INV100010 | C11: E003 | D11: P006 | E11: B002 | F11: 11 | G11: 1171.23
A12: 46200 | B12: INV100011 | C12: E002 | D12: P010 | E12: B001 | F12: 9 | G12: 1560.38
A13: 46133 | B13: INV100012 | C13: E008 | D13: P007 | E13: B004 | F13: 11 | G13: 3128.4
... A86: 46113 | B86: INV100085 | C86: E002 | D86: P007 | E86: B001 | F86: 12 | G86: 3488.78
A87: 46119 | B87: INV100086 | D87: P004 | E87: B001 | F87: 8 | G87: 1259.52
A88: 46172 | B88: INV100087 | C88: E009 | D88: P009 | E88: B005 | F88: 8 | G88: 2890.62
A89: 46177 | B89: INV100088 | C89: E007 | D89: P009 | E89: B004 | F89: 3 | G89: 1065.59
A90: 46173 | B90: INV100089 | C90: E008 | D90: P005 | E90: B004 | F90: 11 | G90: 1276.07
A91: 46179 | B91: INV100090 | C91: E008 | D91: P011 | E91: B004 | F91: 8 | G91: 2694.71
A92: 46149 | B92: INV100091 | C92: E004 | D92: P005 | E92: B002 | F92: 9 | G92: 1069.56
A93: 46132 | B93: INV100092 | C93: E004 | D93: P007 | E93: B002 | F93: 12 | G93: 3624.49
A94: 46166 | B94: INV100093 | C94: E007 | D94: P006 | E94: B004 | F94: 7 | G94: 764.25
A95: 46166 | B95: INV100094 | C95: E007 | D95: P010 | E95: B001 | F95: 10 | G95: 1813.27
A96: 46113 | B96: INV100095 | C96: E006 | D96: P005 | E96: B003 | F96: 7 | G96: 785.75
A97: 46182 | B97: INV100096 | C97: E010 | D97: P004 | E97: B005 | F97: 5 | G97: 758.16
A98: 46116 | B98: INV100097 | C98: E007 | D98: P006 | E98: B004 | F98: 7 | G98: 703.09
A99: 46172 | B99: INV100098 | C99: E003 | D99: P010 | E99: B002 | F99: 7 | G99: 1235.53
... A112: 46160 | B112: INV100111 | C112: E002 | D112: P009 | E112: B001 | F112: 1 | G112: 350.24
A113: 31-Feb-2026 | B113: INV100112 | C113: E002 | D113: P007 | E113: B004 | F113: 12 | G113: 3651.7
A114: 46135 | B114: INV100113 | C114: E009 | D114: P011 | E114: B005 | F114: 9 | G114: 2775.55
A115: 46172 | B115: INV100114 | C115: E007 | D115: P012 | E115: B004 | F115: 6 | G115: 1238.96
A116: 46124 | B116: INV100115 | C116: E005 | D116: P008 | E116: B003 | F116: 8 | G116: 1937.77
A117: 46198 | B117: INV100116 | C117: E007 | D117: P006 | E117: B004 | F117: 6 | G117: 645.6
A118: 46140 | B118: INV100117 | C118: E006 | D118: P005 | E118: B003 | F118: 10 | G118: 1099.03
A119: 46148 | B119: INV100118 | C119: E009 | D119: P001 | E119: B005 | F119: 4 | G119: 1662.74
A120: 46165 | B120: INV100119 | C120: E008 | D120: P009 | E120: B004 | F120: 12 | G120: 4412.63
A121: 46175 | B121: INV100120 | C121: E008 | D121: P001 | E121: B004 | F121: 4 | G121: 1598.47
A122: 46144 | B122: INV100121 | C122: E005 | D122: P011 | E122: B003 | F122: 8 | G122: 2539.35
A123: 46157 | B123: INV100122 | C123: E007 | D123: P012 | E123: B004 | F123: 6 | G123: 1263.61
A124: 46147 | B124: INV100123 | C124: E005 | D124: P005 | E124: B003 | F124: 12 | G124: 1406.72
...

Sheet 02_Employee_Master
A1: Employee_ID | B1: Employee_Name | C1: Department
A2: E001 | B2: Arun Kumar | C2: Sales
A3: E002 | B3: Priya S | C3: Sales
A4: E003 | B4: Rahul M | C4: Sales
A5: E004 | B5: Divya R | C5: Sales
A6: E005 | B6: Karthik P | C6: Sales
A7: E006 | B7: Meena V | C7: Sales
A8: E007 | B8: Suresh B | C8: Sales
A9: E008 | B9: Nandhini K | C9: Sales
A10: E009 | B10: Vignesh R | C10: Sales
A11: E010 | B11: Swetha L | C11: Sales
A12: E007 | B12: Suresh B | C12: Operations

Sheet 03_Product_Master
A1: Product_ID | B1: Product_Name | C1: Category | D1: Standard_Price
A2: P001 | B2: Premium Coffee | C2: Beverages | D2: 420
A3: P002 | B3: Green Tea | C3: Beverages | D3: 280
A4: P003 | B4: Instant Coffee | C4: Beverages | D4: 350
A5: P004 | B5: Cookies Pack | C5: Snacks | D5: 160
A6: P005 | B6: Chocolate Bar | C6: Snacks | D6: 120
A7: P006 | B7: Potato Chips | C7: Snacks | D7: 110
A8: P007 | B8: Shampoo | C8: Personal Care | D8: 310
A9: P008 | B9: Face Wash | C9: Personal Care | D9: 260
A10: P009 | B10: Body Lotion | C10: Personal Care | D10: 390
A11: P010 | B11: Dish Wash | C11: Home Care | D11: 190
A12: P011 | B12: Laundry Liquid | C12: Home Care | D12: 340
A13: P012 | B13: Floor Cleaner | C13: Home Care | D13: 230
A14: P009 | B14: Body Lotion | C14: Beauty | D14: 390

Sheet 04_Branch_Master
A1: Branch_ID | B1: Branch_Name | C1: Region
A2: B001 | B2: Tirupur Central | C2: North
A3: B002 | B3: Avinashi Road | C3: North
A4: B003 | B4: Palladam | C4: South
A5: B004 | B5: Kangeyam | C5: East
A6: B005 | B6: Dharapuram | C6: South
A7: B003 | B7: Palladam | C7: West

Sheet 05_Target_Master
A1: Employee_ID | B1: Month | C1: Monthly_Target | D1: sort | F1: key
A2: E001 | B2: 46113 | C2: 156900 | D2: 1 | E2: =IF(COUNTIFS(A2:A32,A2,B2:B32,B2)>1,"Duplicate","Unique") -> Unique | F2: =A2&"|"&TEXT(B2,"yyyymm") -> E001|202604
A3: E001 | B3: 46143 | C3: 169500 | D3: 2 | F3: =A3&"|"&TEXT(B3,"yyyymm") -> E001|202605
A4: E001 | B4: 46174 | C4: 150600 | D4: 3 | F4: =A4&"|"&TEXT(B4,"yyyymm") -> E001|202606
A5: E002 | B5: 46113 | C5: 122300 | D5: 4 | F5: =A5&"|"&TEXT(B5,"yyyymm") -> E002|202604
A6: E002 | B6: 46143 | C6: 132100 | D6: 5 | F6: =A6&"|"&TEXT(B6,"yyyymm") -> E002|202605
A7: E002 | B7: 46174 | C7: 117400 | D7: 6 | F7: =A7&"|"&TEXT(B7,"yyyymm") -> E002|202606
A8: E003 | B8: 46113 | C8: 116600 | D8: 7 | F8: =A8&"|"&TEXT(B8,"yyyymm") -> E003|202604
A9: E003 | B9: 46143 | C9: 126000 | D9: 8 | F9: =A9&"|"&TEXT(B9,"yyyymm") -> E003|202605
A10: E003 | B10: 46174 | C10: 112000 | D10: 9 | F10: =A10&"|"&TEXT(B10,"yyyymm") -> E003|202606
A11: E004 | B11: 46113 | C11: 163600 | D11: 10 | F11: =A11&"|"&TEXT(B11,"yyyymm") -> E004|202604
A12: E004 | B12: 46143 | C12: 176700 | D12: 11 | F12: =A12&"|"&TEXT(B12,"yyyymm") -> E004|202605
A13: E004 | B13: 46174 | C13: 157100 | D13: 12 | F13: =A13&"|"&TEXT(B13,"yyyymm") -> E004|202606
A14: E004 | B14: 46143 | C14: 155000 | D14: 13 | E14: =IF(COUNTIFS($A$2:$A$32,A14,$B$2:$B$32,B14)>1,"Duplicate","Unique") -> Duplicate | F14: =A14&"|"&TEXT(B14,"yyyymm") -> E004|202605
A15: E005 | B15: 46113 | C15: 133000 | D15: 14 | F15: =A15&"|"&TEXT(B15,"yyyymm") -> E005|202604
A16: E005 | B16: 46143 | C16: 143700 | D16: 15 | F16: =A16&"|"&TEXT(B16,"yyyymm") -> E005|202605
A17: E005 | B17: 46174 | C17: 127700 | D17: 16 | F17: =A17&"|"&TEXT(B17,"yyyymm") -> E005|202606
A18: E006 | B18: 46113 | C18: 131000 | D18: 17 | F18: =A18&"|"&TEXT(B18,"yyyymm") -> E006|202604
A19: E006 | B19: 46143 | C19: 141500 | D19: 18 | F19: =A19&"|"&TEXT(B19,"yyyymm") -> E006|202605
A20: E006 | B20: 46174 | C20: 125800 | D20: 19 | F20: =A20&"|"&TEXT(B20,"yyyymm") -> E006|202606
A21: E007 | B21: 46113 | C21: 129600 | D21: 20 | F21: =A21&"|"&TEXT(B21,"yyyymm") -> E007|202604
A22: E007 | B22: 46143 | C22: 140000 | D22: 21 | F22: =A22&"|"&TEXT(B22,"yyyymm") -> E007|202605
A23: E007 | B23: 46174 | C23: 124400 | D23: 22 | F23: =A23&"|"&TEXT(B23,"yyyymm") -> E007|202606
A24: E008 | B24: 46113 | C24: 124100 | D24: 23 | F24: =A24&"|"&TEXT(B24,"yyyymm") -> E008|202604
A25: E008 | B25: 46143 | C25: 134100 | D25: 24 | F25: =A25&"|"&TEXT(B25,"yyyymm") -> E008|202605
A26: E008 | B26: 46174 | C26: 119200 | D26: 25 | F26: =A26&"|"&TEXT(B26,"yyyymm") -> E008|202606
... A32: E010 | B32: 46174 | C32: 116800 | D32: 31 | F32: =A32&"|"&TEXT(B32,"yyyymm") -> E010|202606

Sheet 06_Issues_log
A1: Issue Type | B1: Sheet | C1: Row / ID | D1: Count | E1: What I Found | F1: Proposed Action
A2: Invalid Date | B2: 01_Sales_Data | C2: 113 | D2: 1 | E2: Invalid date - 31-Feb | F2: Check for original transaction data
A3: Date format | B3: 01_Sales_Data | C3: 369 | D3: 1 | E3: Date format is different | F3: Date format could be changed
A4: Invalid Date | B4: 01_Sales_Data | C4: 746 | D4: 1 | E4: Has text Not a date | F4: Check for original transaction data
A6: Duplicate Invoice id | B6: 01_Sales_Data | C6: 50,51, 200,201, 500,501 | D6: 6 | E6: INV100049, INV100199, INV100499 are repeated | F6: Check for original transaction data
A8: Missing Employee id | B8: 01_Sales_Data | C8: 87, 218 | D8: 2 | E8: Employee_id is blank | F8: Check for original transaction data
A9: Invalid_Employee_id | B9: 01_Sales_Data | C9: 423, 614 | D9: 2 | E9: E000, E999 are invlaid Employee_id | F9: Check for original transaction data
A11: Missing Product_id | B11: 01_Sales_Data | C11: 135, 346 | D11: 2 | E11: Product_id is blank | F11: Check for original transaction data
A12: Invalid Product_id | B12: 01_Sales_Data | C12: 457, 703 | D12: 2 | E12: P000, P999 are invalid product_id | F12: Check for original transaction data
A14: Missing Branch id | B14: 01_Sales_Data | C14: 164, 574 | D14: 2 | E14: Branch id is blank | F14: Check for original transaction data
A15: Invalid Branch id | B15: 01_Sales_Data | C15: 290, 640 | D15: 2 | E15: B000, B999 are invlaid branch id | F15: Check for original transaction data
A17: Invalid Quantity | B17: 01_Sales_Data | C17: 532, 691 | D17: 3 | E17: the values are 0 and negative | F17: Check for original transaction data
A19: Missing Sales Amount | B19: 01_Sales_Data | C19: 304625 | D19: 2 | E19: Sales amounts are missing | F19: Check for original transaction data
A21: Duplicate Master record | B21: 02_Employee_Master | C21: 12 | D21: 1 | E21: E007 is ties with 2 departments (sales and operations) | F21: Need to check with businees operations
A22: Duplicate Master record | B22: 03_Product_Master | C22: 14 | D22: 1 | E22: P009 has 2 different category | F22: Need to check with businees operations
A23: Duplicate Master record | B23: 04_Branch_Master | C23: 7 | D23: 1 | E23: B003 is tied with Palladam South and West | F23: Need to check with businees operations
A24: Target Master issues | B24: 05_Target_Master | C24: 12, 14 | D24: 2 | E24: E004 - May month has two targets | F24: Need to check with businees operations - Get correct target and remove other one

Sheet 03_Clean_data
A1: Date | B1: Invoice_ID | C1: Employee_ID | D1: Product_ID | E1: Branch_ID | F1: Quantity | G1: Sales_Amount | H1: Invoice_dup_check | I1: Data quality check | J1: employee id check | K1: Employee name | L1: Department name | M1: Product_id_check | N1: Product name | O1: Category | P1: standard price | Q1: Branch id check | R1: Branch name | S1: Region | T1: target key | U1: target amount
A2: 46199 | B2: INV100001 | C2: E009 | D2: P002 | E2: B005 | F2: 1 | G2: 279 | H2: =IF(COUNTIF(tbl_clean_sales[Invoice_ID],tbl_clean_sales[[#This Row],[Invoice_ID]])>1,"Duplicate","Unique") -> Unique | J2: =IF(tbl_clean_sales[[#This Row],[Employee_ID]]="","Missing",IFERROR(IF(VLOOKUP(tbl_clean_sales[[#This Row],[Employee_ID]],'02_Employee_Master'!$A$1:$C$12,1,FALSE)=tbl_clean_sales[[#This Row],[Employee_ID]],"Valid","Invalid"),"Invalid")) -> Valid | K2: =IFERROR(VLOOKUP(tbl_clean_sales[[#This Row],[Employee_ID]],'02_Employee_Master'!$A$1:$C$12,2,FALSE),"Employee Name Missing") -> Vignesh R | L2: =IFERROR(VLOOKUP(tbl_clean_sales[[#This Row],[Employee_ID]],'02_Employee_Master'!$A$1:$C$12,3,FALSE),"Department Name Missing") -> Sales | M2: =IF('03_Clean_data'!D2="","Missing",IFERROR(IF(VLOOKUP(D2,'03_Product_Master'!$A$1:$D$14,1,FALSE)='03_Clean_data'!D2,"Valid","Invalid"),"Invalid")) -> Valid | N2: =IFERROR(VLOOKUP(tbl_clean_sales[[#This Row],[Product_ID]],'03_Product_Master'!$A$1:$D$14,2,FALSE),"Missing") -> Green Tea | O2: =IFERROR(VLOOKUP(tbl_clean_sales[[#This Row],[Product_ID]],'03_Product_Master'!$A$1:$D$14,3,FALSE),"Missing") -> Beverages | P2: =IFERROR(VLOOKUP(tbl_clean_sales[[#This Row],[Product_ID]],'03_Product_Master'!$A$1:$D$14,4,FALSE),"Missing") -> 280 | Q2: =IF('03_Clean_data'!E2="","Missing",IFERROR(IF(VLOOKUP(E2,'04_Branch_Master'!$A$1:$C$7,1,FALSE)='03_Clean_data'!E2,"Valid","Invalid"),"Invalid")) -> Valid | R2: =IFERROR(VLOOKUP(tbl_clean_sales[[#This Row],[Branch_ID]],'04_Branch_Master'!$A$1:$C$7,2,FALSE),"Missing") -> Dharapuram | S2: =IFERROR(VLOOKUP(tbl_clean_sales[[#This Row],[Branch_ID]],'04_Branch_Master'!$A$1:$C$7,3,FALSE),"Missing") -> South | T2: =C2&"|"&TEXT(tbl_clean_sales[[#This Row],[Date]],"yyyymm") -> E009|202606 | U2: =IFERROR(INDEX('05_Target_Master'!$A$1:$F$32,MATCH(tbl_clean_sales[[#This Row],[target key]],'05_Target_Master'!$F$1:$F$32,0),3),"Missing") -> 156700
A3: 46140 | B3: INV100002 | C3: E004 | D3: P009 | E3: B002 | F3: 9 | G3: 3426.25 | H3: =IF(COUNTIF(tbl_clean_sales[Invoice_ID],tbl_clean_sales[[#This Row],[Invoice_ID]])>1,"Duplicate","Unique") -> Unique | J3: =IF(tbl_clean_sales[[#This Row],[Employee_ID]]="","Missing",IFERROR(IF(VLOOKUP(tbl_clean_sales[[#This Row],[Employee_ID]],'02_Employee_Master'!$A$1:$C$12,1,FALSE)=tbl_clean_sales[[#This Row],[Employee_ID]],"Valid","Invalid"),"Invalid")) -> Valid | K3: =IFERROR(VLOOKUP(tbl_clean_sales[[#This Row],[Employee_ID]],'02_Employee_Master'!$A$1:$C$12,2,FALSE),"Employee Name Missing") -> Divya R | L3: =IFERROR(VLOOKUP(tbl_clean_sales[[#This Row],[Employee_ID]],'02_Employee_Master'!$A$1:$C$12,3,FALSE),"Department Name Missing") -> Sales | M3: =IF('03_Clean_data'!D3="","Missing",IFERROR(IF(VLOOKUP(D3,'03_Product_Master'!$A$1:$D$14,1,FALSE)='03_Clean_data'!D3,"Valid","Invalid"),"Invalid")) -> Valid | N3: =IFERROR(VLOOKUP(tbl_clean_sales[[#This Row],[Product_ID]],'03_Product_Master'!$A$1:$D$14,2,FALSE),"Missing") -> Body Lotion | O3: =IFERROR(VLOOKUP(tbl_clean_sales[[#This Row],[Product_ID]],'03_Product_Master'!$A$1:$D$14,3,FALSE),"Missing") -> Personal Care | P3: =IFERROR(VLOOKUP(tbl_clean_sales[[#This Row],[Product_ID]],'03_Product_Master'!$A$1:$D$14,4,FALSE),"Missing") -> 390 | Q3: =IF('03_Clean_data'!E3="","Missing",IFERROR(IF(VLOOKUP(E3,'04_Branch_Master'!$A$1:$C$7,1,FALSE)='03_Clean_data'!E3,"Valid","Invalid"),"Invalid")) -> Valid | R3: =IFERROR(VLOOKUP(tbl_clean_sales[[#This Row],[Branch_ID]],'04_Branch_Master'!$A$1:$C$7,2,FALSE),"Missing") -> Avinashi Road | S3: =IFERROR(VLOOKUP(tbl_clean_sales[[#This Row],[Branch_ID]],'04_Branch_Master'!$A$1:$C$7,3,FALSE),"Missing") -> North | T3: =C3&"|"&TEXT(tbl_clean_sales[[#This Row],[Date]],"yyyymm") -> E004|202604 | U3: =IFERROR(INDEX('05_Target_Master'!$A$1:$F$32,MATCH(tbl_clean_sales[[#This Row],[target key]],'05_Target_Master'!$F$1:$F$32,0),3),"Missing") -> 163600
A4: 46196 | B4: INV100003 | C4: E009 | D4: P007 | E4: B005 | F4: 10 | G4: 2996.51 | H4: =IF(COUNTIF(tbl_clean_sales[Invoice_ID],tbl_clean_sales[[#This Row],[Invoice_ID]])>1,"Duplicate","Unique") -> Unique | J4: =IF(tbl_clean_sales[[#This Row],[Employee_ID]]="","Missing",IFERROR(IF(VLOOKUP(tbl_clean_sales[[#This Row],[Employee_ID]],'02_Employee_Master'!$A$1:$C$12,1,FALSE)=tbl_clean_sales[[#This Row],[Employee_ID]],"Valid","Invalid"),"Invalid")) -> Valid | K4: =IFERROR(VLOOKUP(tbl_clean_sales[[#This Row],[Employee_ID]],'02_Employee_Master'!$A$1:$C$12,2,FALSE),"Employee Name Missing") -> Vignesh R | L4: =IFERROR(VLOOKUP(tbl_clean_sales[[#This Row],[Employee_ID]],'02_Employee_Master'!$A$1:$C$12,3,FALSE),"Department Name Missing") -> Sales | M4: =IF('03_Clean_data'!D4="","Missing",IFERROR(IF(VLOOKUP(D4,'03_Product_Master'!$A$1:$D$14,1,FALSE)='03_Clean_data'!D4,"Valid","Invalid"),"Invalid")) -> Valid | N4: =IFERROR(VLOOKUP(tbl_clean_sales[[#This Row],[Product_ID]],'03_Product_Master'!$A$1:$D$14,2,FALSE),"Missing") -> Shampoo | O4: =IFERROR(VLOOKUP(tbl_clean_sales[[#This Row],[Product_ID]],'03_Product_Master'!$A$1:$D$14,3,FALSE),"Missing") -> Personal Care | P4: =IFERROR(VLOOKUP(tbl_clean_sales[[#This Row],[Product_ID]],'03_Product_Master'!$A$1:$D$14,4,FALSE),"Missing") -> 310 | Q4: =IF('03_Clean_data'!E4="","Missing",IFERROR(IF(VLOOKUP(E4,'04_Branch_Master'!$A$1:$C$7,1,FALSE)='03_Clean_data'!E4,"Valid","Invalid"),"Invalid")) -> Valid | R4: =IFERROR(VLOOKUP(tbl_clean_sales[[#This Row],[Branch_ID]],'04_Branch_Master'!$A$1:$C$7,2,FALSE),"Missing") -> Dharapuram | S4: =IFERROR(VLOOKUP(tbl_clean_sales[[#This Row],[Branch_ID]],'04_Branch_Master'!$A$1:$C$7,3,FALSE),"Missing") -> South | T4: =C4&"|"&TEXT(tbl_clean_sales[[#This Row],[Date]],"yyyymm") -> E009|202606 | U4: =IFERROR(INDEX('05_Target_Master'!$A$1:$F$32,MATCH(tbl_clean_sales[[#This Row],[target key]],'05_Target_Master'!$F$1:$F$32,0),3),"Missing") -> 156700
A5: 46113 | B5: INV100004 | C5: E003 | D5: P012 | E5: B002 | F5: 5 | G5: 1128.54 | H5: =IF(COUNTIF(tbl_clean_sales[Invoice_ID],tbl_clean_sales[[#This Row],[Invoice_ID]])>1,"Duplicate","Unique") -> Unique | J5: =IF(tbl_clean_sales[[#This Row],[Employee_ID]]="","Missing",IFERROR(IF(VLOOKUP(tbl_clean_sales[[#This Row],[Employee_ID]],'02_Employee_Master'!$A$1:$C$12,1,FALSE)=tbl_clean_sales[[#This Row],[Employee_ID]],"Valid","Invalid"),"Invalid")) -> Valid | K5: =IFERROR(VLOOKUP(tbl_clean_sales[[#This Row],[Employee_ID]],'02_Employee_Master'!$A$1:$C$12,2,FALSE),"Employee Name Missing") -> Rahul M | L5: =IFERROR(VLOOKUP(tbl_clean_sales[[#This Row],[Employee_ID]],'02_Employee_Master'!$A$1:$C$12,3,FALSE),"Department Name Missing") -> Sales | M5: =IF('03_Clean_data'!D5="","Missing",IFERROR(IF(VLOOKUP(D5,'03_Product_Master'!$A$1:$D$14,1,FALSE)='03_Clean_data'!D5,"Valid","Invalid"),"Invalid")) -> Valid | N5: =IFERROR(VLOOKUP(tbl_clean_sales[[#This Row],[Product_ID]],'03_Product_Master'!$A$1:$D$14,2,FALSE),"Missing") -> Floor Cleaner | O5: =IFERROR(VLOOKUP(tbl_clean_sales[[#This Row],[Product_ID]],'03_Product_Master'!$A$1:$D$14,3,FALSE),"Missing") -> Home Care | P5: =IFERROR(VLOOKUP(tbl_clean_sales[[#This Row],[Product_ID]],'03_Product_Master'!$A$1:$D$14,4,FALSE),"Missing") -> 230 | Q5: =IF('03_Clean_data'!E5="","Missing",IFERROR(IF(VLOOKUP(E5,'04_Branch_Master'!$A$1:$C$7,1,FALSE)='03_Clean_data'!E5,"Valid","Invalid"),"Invalid")) -> Valid | R5: =IFERROR(VLOOKUP(tbl_clean_sales[[#This Row],[Branch_ID]],'04_Branch_Master'!$A$1:$C$7,2,FALSE),"Missing") -> Avinashi Road | S5: =IFERROR(VLOOKUP(tbl_clean_sales[[#This Row],[Branch_ID]],'04_Branch_Master'!$A$1:$C$7,3,FALSE),"Missing") -> North | T5: =C5&"|"&TEXT(tbl_clean_sales[[#This Row],[Date]],"yyyymm") -> E003|202604 | U5: =IFERROR(INDEX('05_Target_Master'!$A$1:$F$32,MATCH(tbl_clean_sales[[#This Row],[target key]],'05_Target_Master'!$F$1:$F$32,0),3),"Missing") -> 116600
A6: 46156 | B6: INV100005 | C6: E002 | D6: P002 | E6: B001 | F6: 6 | G6: 1509.15 | H6: =IF(COUNTIF(tbl_clean_sales[Invoice_ID],tbl_clean_sales[[#This Row],[Invoice_ID]])>1,"Duplicate","Unique") -> Unique | J6: =IF(tbl_clean_sales[[#This Row],[Employee_ID]]="","Missing",IFERROR(IF(VLOOKUP(tbl_clean_sales[[#This Row],[Employee_ID]],'02_Employee_Master'!$A$1:$C$12,1,FALSE)=tbl_clean_sales[[#This Row],[Employee_ID]],"Valid","Invalid"),"Invalid")) -> Valid | K6: =IFERROR(VLOOKUP(tbl_clean_sales[[#This Row],[Employee_ID]],'02_Employee_Master'!$A$1:$C$12,2,FALSE),"Employee Name Missing") -> Priya S | L6: =IFERROR(VLOOKUP(tbl_clean_sales[[#This Row],[Employee_ID]],'02_Employee_Master'!$A$1:$C$12,3,FALSE),"Department Name Missing") -> Sales | M6: =IF('03_Clean_data'!D6="","Missing",IFERROR(IF(VLOOKUP(D6,'03_Product_Master'!$A$1:$D$14,1,FALSE)='03_Clean_data'!D6,"Valid","Invalid"),"Invalid")) -> Valid | N6: =IFERROR(VLOOKUP(tbl_clean_sales[[#This Row],[Product_ID]],'03_Product_Master'!$A$1:$D$14,2,FALSE),"Missing") -> Green Tea | O6: =IFERROR(VLOOKUP(tbl_clean_sales[[#This Row],[Product_ID]],'03_Product_Master'!$A$1:$D$14,3,FALSE),"Missing") -> Beverages | P6: =IFERROR(VLOOKUP(tbl_clean_sales[[#This Row],[Product_ID]],'03_Product_Master'!$A$1:$D$14,4,FALSE),"Missing") -> 280 | Q6: =IF('03_Clean_data'!E6="","Missing",IFERROR(IF(VLOOKUP(E6,'04_Branch_Master'!$A$1:$C$7,1,FALSE)='03_Clean_data'!E6,"Valid","Invalid"),"Invalid")) -> Valid | R6: =IFERROR(VLOOKUP(tbl_clean_sales[[#This Row],[Branch_ID]],'04_Branch_Master'!$A$1:$C$7,2,FALSE),"Missing") -> Tirupur Central | S6: =IFERROR(VLOOKUP(tbl_clean_sales[[#This Row],[Branch_ID]],'04_Branch_Master'!$A$1:$C$7,3,FALSE),"Missing") -> North | T6: =C6&"|"&TEXT(tbl_clean_sales[[#This Row],[Date]],"yyyymm") -> E002|202605 | U6: =IFERROR(INDEX('05_Target_Master'!$A$1:$F$32,MATCH(tbl_clean_sales[[#This Row],[target key]],'05_Target_Master'!$F$1:$F$32,0),3),"Missing") -> 132100
A7: 46190 | B7: INV100006 | C7: E005 | D7: P001 | E7: B003 | F7: 9 | G7: 3723.38 | H7: =IF(COUNTIF(tbl_clean_sales[Invoice_ID],tbl_clean_sales[[#This Row],[Invoice_ID]])>1,"Duplicate","Unique") -> Unique | J7: =IF(tbl_clean_sales[[#This Row],[Employee_ID]]="","Missing",IFERROR(IF(VLOOKUP(tbl_clean_sales[[#This Row],[Employee_ID]],'02_Employee_Master'!$A$1:$C$12,1,FALSE)=tbl_clean_sales[[#This Row],[Employee_ID]],"Valid","Invalid"),"Invalid")) -> Valid | K7: =IFERROR(VLOOKUP(tbl_clean_sales[[#This Row],[Employee_ID]],'02_Employee_Master'!$A$1:$C$12,2,FALSE),"Employee Name Missing") -> Karthik P | L7: =IFERROR(VLOOKUP(tbl_clean_sales[[#This Row],[Employee_ID]],'02_Employee_Master'!$A$1:$C$12,3,FALSE),"Department Name Missing") -> Sales | M7: =IF('03_Clean_data'!D7="","Missing",IFERROR(IF(VLOOKUP(D7,'03_Product_Master'!$A$1:$D$14,1,FALSE)='03_Clean_data'!D7,"Valid","Invalid"),"Invalid")) -> Valid | N7: =IFERROR(VLOOKUP(tbl_clean_sales[[#This Row],[Product_ID]],'03_Product_Master'!$A$1:$D$14,2,FALSE),"Missing") -> Premium Coffee | O7: =IFERROR(VLOOKUP(tbl_clean_sales[[#This Row],[Product_ID]],'03_Product_Master'!$A$1:$D$14,3,FALSE),"Missing") -> Beverages | P7: =IFERROR(VLOOKUP(tbl_clean_sales[[#This Row],[Product_ID]],'03_Product_Master'!$A$1:$D$14,4,FALSE),"Missing") -> 420 | Q7: =IF('03_Clean_data'!E7="","Missing",IFERROR(IF(VLOOKUP(E7,'04_Branch_Master'!$A$1:$C$7,1,FALSE)='03_Clean_data'!E7,"Valid","Invalid"),"Invalid")) -> Valid | R7: =IFERROR(VLOOKUP(tbl_clean_sales[[#This Row],[Branch_ID]],'04_Branch_Master'!$A$1:$C$7,2,FALSE),"Missing") -> Palladam | S7: =IFERROR(VLOOKUP(tbl_clean_sales[[#This Row],[Branch_ID]],'04_Branch_Master'!$A$1:$C$7,3,FALSE),"Missing") -> South | T7: =C7&"|"&TEXT(tbl_clean_sales[[#This Row],[Date]],"yyyymm") -> E005|202606 | U7: =IFERROR(INDEX('05_Target_Master'!$A$1:$F$32,MATCH(tbl_clean_sales[[#This Row],[target key]],'05_Target_Master'!$F$1:$F$32,0),3),"Missing") -> 127700
A8: 46161 | B8: INV100007 | C8: E002 | D8: P009 | E8: B001 | F8: 11 | G8: 3971.59 | H8: =IF(COUNTIF(tbl_clean_sales[Invoice_ID],tbl_clean_sales[[#This Row],[Invoice_ID]])>1,"Duplicate","Unique") -> Unique | J8: =IF(tbl_clean_sales[[#This Row],[Employee_ID]]="","Missing",IFERROR(IF(VLOOKUP(tbl_clean_sales[[#This Row],[Employee_ID]],'02_Employee_Master'!$A$1:$C$12,1,FALSE)=tbl_clean_sales[[#This Row],[Employee_ID]],"Valid","Invalid"),"Invalid")) -> Valid | K8: =IFERROR(VLOOKUP(tbl_clean_sales[[#This Row],[Employee_ID]],'02_Employee_Master'!$A$1:$C$12,2,FALSE),"Employee Name Missing") -> Priya S | L8: =IFERROR(VLOOKUP(tbl_clean_sales[[#This Row],[Employee_ID]],'02_Employee_Master'!$A$1:$C$12,3,FALSE),"Department Name Missing") -> Sales | M8: =IF('03_Clean_data'!D8="","Missing",IFERROR(IF(VLOOKUP(D8,'03_Product_Master'!$A$1:$D$14,1,FALSE)='03_Clean_data'!D8,"Valid","Invalid"),"Invalid")) -> Valid | N8: =IFERROR(VLOOKUP(tbl_clean_sales[[#This Row],[Product_ID]],'03_Product_Master'!$A$1:$D$14,2,FALSE),"Missing") -> Body Lotion | O8: =IFERROR(VLOOKUP(tbl_clean_sales[[#This Row],[Product_ID]],'03_Product_Master'!$A$1:$D$14,3,FALSE),"Missing") -> Personal Care | P8: =IFERROR(VLOOKUP(tbl_clean_sales[[#This Row],[Product_ID]],'03_Product_Master'!$A$1:$D$14,4,FALSE),"Missing") -> 390 | Q8: =IF('03_Clean_data'!E8="","Missing",IFERROR(IF(VLOOKUP(E8,'04_Branch_Master'!$A$1:$C$7,1,FALSE)='03_Clean_data'!E8,"Valid","Invalid"),"Invalid")) -> Valid | R8: =IFERROR(VLOOKUP(tbl_clean_sales[[#This Row],[Branch_ID]],'04_Branch_Master'!$A$1:$C$7,2,FALSE),"Missing") -> Tirupur Central | S8: =IFERROR(VLOOKUP(tbl_clean_sales[[#This Row],[Branch_ID]],'04_Branch_Master'!$A$1:$C$7,3,FALSE),"Missing") -> North | T8: =C8&"|"&TEXT(tbl_clean_sales[[#This Row],[Date]],"yyyymm") -> E002|202605 | U8: =IFERROR(INDEX('05_Target_Master'!$A$1:$F$32,MATCH(tbl_clean_sales[[#This Row],[target key]],'05_Target_Master'!$F$1:$F$32,0),3),"Missing") -> 132100
A9: 46159 | B9: INV100008 | C9: E010 | D9: P004 | E9: B005 | F9: 1 | G9: 147.3 | H9: =IF(COUNTIF(tbl_clean_sales[Invoice_ID],tbl_clean_sales[[#This Row],[Invoice_ID]])>1,"Duplicate","Unique") -> Unique | J9: =IF(tbl_clean_sales[[#This Row],[Employee_ID]]="","Missing",IFERROR(IF(VLOOKUP(tbl_clean_sales[[#This Row],[Employee_ID]],'02_Employee_Master'!$A$1:$C$12,1,FALSE)=tbl_clean_sales[[#This Row],[Employee_ID]],"Valid","Invalid"),"Invalid")) -> Valid | K9: =IFERROR(VLOOKUP(tbl_clean_sales[[#This Row],[Employee_ID]],'02_Employee_Master'!$A$1:$C$12,2,FALSE),"Employee Name Missing") -> Swetha L | L9: =IFERROR(VLOOKUP(tbl_clean_sales[[#This Row],[Employee_ID]],'02_Employee_Master'!$A$1:$C$12,3,FALSE),"Department Name Missing") -> Sales | M9: =IF('03_Clean_data'!D9="","Missing",IFERROR(IF(VLOOKUP(D9,'03_Product_Master'!$A$1:$D$14,1,FALSE)='03_Clean_data'!D9,"Valid","Invalid"),"Invalid")) -> Valid | N9: =IFERROR(VLOOKUP(tbl_clean_sales[[#This Row],[Product_ID]],'03_Product_Master'!$A$1:$D$14,2,FALSE),"Missing") -> Cookies Pack | O9: =IFERROR(VLOOKUP(tbl_clean_sales[[#This Row],[Product_ID]],'03_Product_Master'!$A$1:$D$14,3,FALSE),"Missing") -> Snacks | P9: =IFERROR(VLOOKUP(tbl_clean_sales[[#This Row],[Product_ID]],'03_Product_Master'!$A$1:$D$14,4,FALSE),"Missing") -> 160 | Q9: =IF('03_Clean_data'!E9="","Missing",IFERROR(IF(VLOOKUP(E9,'04_Branch_Master'!$A$1:$C$7,1,FALSE)='03_Clean_data'!E9,"Valid","Invalid"),"Invalid")) -> Valid | R9: =IFERROR(VLOOKUP(tbl_clean_sales[[#This Row],[Branch_ID]],'04_Branch_Master'!$A$1:$C$7,2,FALSE),"Missing") -> Dharapuram | S9: =IFERROR(VLOOKUP(tbl_clean_sales[[#This Row],[Branch_ID]],'04_Branch_Master'!$A$1:$C$7,3,FALSE),"Missing") -> South | T9: =C9&"|"&TEXT(tbl_clean_sales[[#This Row],[Date]],"yyyymm") -> E010|202605 | U9: =IFERROR(INDEX('05_Target_Master'!$A$1:$F$32,MATCH(tbl_clean_sales[[#This Row],[target key]],'05_Target_Master'!$F$1:$F$32,0),3),"Missing") -> 131500
A10: 46150 | B10: INV100009 | C10: E002 | D10: P004 | E10: B004 | F10: 5 | G10: 756.47 | H10: =IF(COUNTIF(tbl_clean_sales[Invoice_ID],tbl_clean_sales[[#This Row],[Invoice_ID]])>1,"Duplicate","Unique") -> Unique | J10: =IF(tbl_clean_sales[[#This Row],[Employee_ID]]="","Missing",IFERROR(IF(VLOOKUP(tbl_clean_sales[[#This Row],[Employee_ID]],'02_Employee_Master'!$A$1:$C$12,1,FALSE)=tbl_clean_sales[[#This Row],[Employee_ID]],"Valid","Invalid"),"Invalid")) -> Valid | K10: =IFERROR(VLOOKUP(tbl_clean_sales[[#This Row],[Employee_ID]],'02_Employee_Master'!$A$1:$C$12,2,FALSE),"Employee Name Missing") -> Priya S | L10: =IFERROR(VLOOKUP(tbl_clean_sales[[#This Row],[Employee_ID]],'02_Employee_Master'!$A$1:$C$12,3,FALSE),"Department Name Missing") -> Sales | M10: =IF('03_Clean_data'!D10="","Missing",IFERROR(IF(VLOOKUP(D10,'03_Product_Master'!$A$1:$D$14,1,FALSE)='03_Clean_data'!D10,"Valid","Invalid"),"Invalid")) -> Valid | N10: =IFERROR(VLOOKUP(tbl_clean_sales[[#This Row],[Product_ID]],'03_Product_Master'!$A$1:$D$14,2,FALSE),"Missing") -> Cookies Pack | O10: =IFERROR(VLOOKUP(tbl_clean_sales[[#This Row],[Product_ID]],'03_Product_Master'!$A$1:$D$14,3,FALSE),"Missing") -> Snacks | P10: =IFERROR(VLOOKUP(tbl_clean_sales[[#This Row],[Product_ID]],'03_Product_Master'!$A$1:$D$14,4,FALSE),"Missing") -> 160 | Q10: =IF('03_Clean_data'!E10="","Missing",IFERROR(IF(VLOOKUP(E10,'04_Branch_Master'!$A$1:$C$7,1,FALSE)='03_Clean_data'!E10,"Valid","Invalid"),"Invalid")) -> Valid | R10: =IFERROR(VLOOKUP(tbl_clean_sales[[#This Row],[Branch_ID]],'04_Branch_Master'!$A$1:$C$7,2,FALSE),"Missing") -> Kangeyam | S10: =IFERROR(VLOOKUP(tbl_clean_sales[[#This Row],[Branch_ID]],'04_Branch_Master'!$A$1:$C$7,3,FALSE),"Missing") -> East | T10: =C10&"|"&TEXT(tbl_clean_sales[[#This Row],[Date]],"yyyymm") -> E002|202605 | U10: =IFERROR(INDEX('05_Target_Master'!$A$1:$F$32,MATCH(tbl_clean_sales[[#This Row],[target key]],'05_Target_Master'!$F$1:$F$32,0),3),"Missing") -> 132100
A11: 46159 | B11: INV100010 | C11: E003 | D11: P006 | E11: B002 | F11: 11 | G11: 1171.23 | H11: =IF(COUNTIF(tbl_clean_sales[Invoice_ID],tbl_clean_sales[[#This Row],[Invoice_ID]])>1,"Duplicate","Unique") -> Unique | J11: =IF(tbl_clean_sales[[#This Row],[Employee_ID]]="","Missing",IFERROR(IF(VLOOKUP(tbl_clean_sales[[#This Row],[Employee_ID]],'02_Employee_Master'!$A$1:$C$12,1,FALSE)=tbl_clean_sales[[#This Row],[Employee_ID]],"Valid","Invalid"),"Invalid")) -> Valid | K11: =IFERROR(VLOOKUP(tbl_clean_sales[[#This Row],[Employee_ID]],'02_Employee_Master'!$A$1:$C$12,2,FALSE),"Employee Name Missing") -> Rahul M | L11: =IFERROR(VLOOKUP(tbl_clean_sales[[#This Row],[Employee_ID]],'02_Employee_Master'!$A$1:$C$12,3,FALSE),"Department Name Missing") -> Sales | M11: =IF('03_Clean_data'!D11="","Missing",IFERROR(IF(VLOOKUP(D11,'03_Product_Master'!$A$1:$D$14,1,FALSE)='03_Clean_data'!D11,"Valid","Invalid"),"Invalid")) -> Valid | N11: =IFERROR(VLOOKUP(tbl_clean_sales[[#This Row],[Product_ID]],'03_Product_Master'!$A$1:$D$14,2,FALSE),"Missing") -> Potato Chips | O11: =IFERROR(VLOOKUP(tbl_clean_sales[[#This Row],[Product_ID]],'03_Product_Master'!$A$1:$D$14,3,FALSE),"Missing") -> Snacks | P11: =IFERROR(VLOOKUP(tbl_clean_sales[[#This Row],[Product_ID]],'03_Product_Master'!$A$1:$D$14,4,FALSE),"Missing") -> 110 | Q11: =IF('03_Clean_data'!E11="","Missing",IFERROR(IF(VLOOKUP(E11,'04_Branch_Master'!$A$1:$C$7,1,FALSE)='03_Clean_data'!E11,"Valid","Invalid"),"Invalid")) -> Valid | R11: =IFERROR(VLOOKUP(tbl_clean_sales[[#This Row],[Branch_ID]],'04_Branch_Master'!$A$1:$C$7,2,FALSE),"Missing") -> Avinashi Road | S11: =IFERROR(VLOOKUP(tbl_clean_sales[[#This Row],[Branch_ID]],'04_Branch_Master'!$A$1:$C$7,3,FALSE),"Missing") -> North | T11: =C11&"|"&TEXT(tbl_clean_sales[[#This Row],[Date]],"yyyymm") -> E003|202605 | U11: =IFERROR(INDEX('05_Target_Master'!$A$1:$F$32,MATCH(tbl_clean_sales[[#This Row],[target key]],'05_Target_Master'!$F$1:$F$32,0),3),"Missing") -> 126000
A12: 46200 | B12: INV100011 | C12: E002 | D12: P010 | E12: B001 | F12: 9 | G12: 1560.38 | H12: =IF(COUNTIF(tbl_clean_sales[Invoice_ID],tbl_clean_sales[[#This Row],[Invoice_ID]])>1,"Duplicate","Unique") -> Unique | J12: =IF(tbl_clean_sales[[#This Row],[Employee_ID]]="","Missing",IFERROR(IF(VLOOKUP(tbl_clean_sales[[#This Row],[Employee_ID]],'02_Employee_Master'!$A$1:$C$12,1,FALSE)=tbl_clean_sales[[#This Row],[Employee_ID]],"Valid","Invalid"),"Invalid")) -> Valid | K12: =IFERROR(VLOOKUP(tbl_clean_sales[[#This Row],[Employee_ID]],'02_Employee_Master'!$A$1:$C$12,2,FALSE),"Employee Name Missing") -> Priya S | L12: =IFERROR(VLOOKUP(tbl_clean_sales[[#This Row],[Employee_ID]],'02_Employee_Master'!$A$1:$C$12,3,FALSE),"Department Name Missing") -> Sales | M12: =IF('03_Clean_data'!D12="","Missing",IFERROR(IF(VLOOKUP(D12,'03_Product_Master'!$A$1:$D$14,1,FALSE)='03_Clean_data'!D12,"Valid","Invalid"),"Invalid")) -> Valid | N12: =IFERROR(VLOOKUP(tbl_clean_sales[[#This Row],[Product_ID]],'03_Product_Master'!$A$1:$D$14,2,FALSE),"Missing") -> Dish Wash | O12: =IFERROR(VLOOKUP(tbl_clean_sales[[#This Row],[Product_ID]],'03_Product_Master'!$A$1:$D$14,3,FALSE),"Missing") -> Home Care | P12: =IFERROR(VLOOKUP(tbl_clean_sales[[#This Row],[Product_ID]],'03_Product_Master'!$A$1:$D$14,4,FALSE),"Missing") -> 190 | Q12: =IF('03_Clean_data'!E12="","Missing",IFERROR(IF(VLOOKUP(E12,'04_Branch_Master'!$A$1:$C$7,1,FALSE)='03_Clean_data'!E12,"Valid","Invalid"),"Invalid")) -> Valid | R12: =IFERROR(VLOOKUP(tbl_clean_sales[[#This Row],[Branch_ID]],'04_Branch_Master'!$A$1:$C$7,2,FALSE),"Missing") -> Tirupur Central | S12: =IFERROR(VLOOKUP(tbl_clean_sales[[#This Row],[Branch_ID]],'04_Branch_Master'!$A$1:$C$7,3,FALSE),"Missing") -> North | T12: =C12&"|"&TEXT(tbl_clean_sales[[#This Row],[Date]],"yyyymm") -> E002|202606 | U12: =IFERROR(INDEX('05_Target_Master'!$A$1:$F$32,MATCH(tbl_clean_sales[[#This Row],[target key]],'05_Target_Master'!$F$1:$F$32,0),3),"Missing") -> 117400
A13: 46133 | B13: INV100012 | C13: E008 | D13: P007 | E13: B004 | F13: 11 | G13: 3128.4 | H13: =IF(COUNTIF(tbl_clean_sales[Invoice_ID],tbl_clean_sales[[#This Row],[Invoice_ID]])>1,"Duplicate","Unique") -> Unique | J13: =IF(tbl_clean_sales[[#This Row],[Employee_ID]]="","Missing",IFERROR(IF(VLOOKUP(tbl_clean_sales[[#This Row],[Employee_ID]],'02_Employee_Master'!$A$1:$C$12,1,FALSE)=tbl_clean_sales[[#This Row],[Employee_ID]],"Valid","Invalid"),"Invalid")) -> Valid | K13: =IFERROR(VLOOKUP(tbl_clean_sales[[#This Row],[Employee_ID]],'02_Employee_Master'!$A$1:$C$12,2,FALSE),"Employee Name Missing") -> Nandhini K | L13: =IFERROR(VLOOKUP(tbl_clean_sales[[#This Row],[Employee_ID]],'02_Employee_Master'!$A$1:$C$12,3,FALSE),"Department Name Missing") -> Sales | M13: =IF('03_Clean_data'!D13="","Missing",IFERROR(IF(VLOOKUP(D13,'03_Product_Master'!$A$1:$D$14,1,FALSE)='03_Clean_data'!D13,"Valid","Invalid"),"Invalid")) -> Valid | N13: =IFERROR(VLOOKUP(tbl_clean_sales[[#This Row],[Product_ID]],'03_Product_Master'!$A$1:$D$14,2,FALSE),"Missing") -> Shampoo | O13: =IFERROR(VLOOKUP(tbl_clean_sales[[#This Row],[Product_ID]],'03_Product_Master'!$A$1:$D$14,3,FALSE),"Missing") -> Personal Care | P13: =IFERROR(VLOOKUP(tbl_clean_sales[[#This Row],[Product_ID]],'03_Product_Master'!$A$1:$D$14,4,FALSE),"Missing") -> 310 | Q13: =IF('03_Clean_data'!E13="","Missing",IFERROR(IF(VLOOKUP(E13,'04_Branch_Master'!$A$1:$C$7,1,FALSE)='03_Clean_data'!E13,"Valid","Invalid"),"Invalid")) -> Valid | R13: =IFERROR(VLOOKUP(tbl_clean_sales[[#This Row],[Branch_ID]],'04_Branch_Master'!$A$1:$C$7,2,FALSE),"Missing") -> Kangeyam | S13: =IFERROR(VLOOKUP(tbl_clean_sales[[#This Row],[Branch_ID]],'04_Branch_Master'!$A$1:$C$7,3,FALSE),"Missing") -> East | T13: =C13&"|"&TEXT(tbl_clean_sales[[#This Row],[Date]],"yyyymm") -> E008|202604 | U13: =IFERROR(INDEX('05_Target_Master'!$A$1:$F$32,MATCH(tbl_clean_sales[[#This Row],[target key]],'05_Target_Master'!$F$1:$F$32,0),3),"Missing") -> 124100
... A50: 46197 | B50: INV100049 | C50: E010 | D50: P010 | E50: B005 | F50: 5 | G50: 926.71 | H50: =IF(COUNTIF(tbl_clean_sales[Invoice_ID],tbl_clean_sales[[#This Row],[Invoice_ID]])>1,"Duplicate","Unique") -> Duplicate | J50: =IF(tbl_clean_sales[[#This Row],[Employee_ID]]="","Missing",IFERROR(IF(VLOOKUP(tbl_clean_sales[[#This Row],[Employee_ID]],'02_Employee_Master'!$A$1:$C$12,1,FALSE)=tbl_clean_sales[[#This Row],[Employee_ID]],"Valid","Invalid"),"Invalid")) -> Valid | K50: =IFERROR(VLOOKUP(tbl_clean_sales[[#This Row],[Employee_ID]],'02_Employee_Master'!$A$1:$C$12,2,FALSE),"Employee Name Missing") -> Swetha L | L50: =IFERROR(VLOOKUP(tbl_clean_sales[[#This Row],[Employee_ID]],'02_Employee_Master'!$A$1:$C$12,3,FALSE),"Department Name Missing") -> Sales | M50: =IF('03_Clean_data'!D50="","Missing",IFERROR(IF(VLOOKUP(D50,'03_Product_Master'!$A$1:$D$14,1,FALSE)='03_Clean_data'!D50,"Valid","Invalid"),"Invalid")) -> Valid | N50: =IFERROR(VLOOKUP(tbl_clean_sales[[#This Row],[Product_ID]],'03_Product_Master'!$A$1:$D$14,2,FALSE),"Missing") -> Dish Wash | O50: =IFERROR(VLOOKUP(tbl_clean_sales[[#This Row],[Product_ID]],'03_Product_Master'!$A$1:$D$14,3,FALSE),"Missing") -> Home Care | P50: =IFERROR(VLOOKUP(tbl_clean_sales[[#This Row],[Product_ID]],'03_Product_Master'!$A$1:$D$14,4,FALSE),"Missing") -> 190 | Q50: =IF('03_Clean_data'!E50="","Missing",IFERROR(IF(VLOOKUP(E50,'04_Branch_Master'!$A$1:$C$7,1,FALSE)='03_Clean_data'!E50,"Valid","Invalid"),"Invalid")) -> Valid | R50: =IFERROR(VLOOKUP(tbl_clean_sales[[#This Row],[Branch_ID]],'04_Branch_Master'!$A$1:$C$7,2,FALSE),"Missing") -> Dharapuram | S50: =IFERROR(VLOOKUP(tbl_clean_sales[[#This Row],[Branch_ID]],'04_Branch_Master'!$A$1:$C$7,3,FALSE),"Missing") -> South | T50: =C50&"|"&TEXT(tbl_clean_sales[[#This Row],[Date]],"yyyymm") -> E010|202606 | U50: =IFERROR(INDEX('05_Target_Master'!$A$1:$F$32,MATCH(tbl_clean_sales[[#This Row],[target key]],'05_Target_Master'!$F$1:$F$32,0),3),"Missing") -> 116800
A51: 46153 | B51: INV100049 | C51: E004 | D51: P005 | E51: B002 | F51: 11 | G51: 1217.75 | H51: =IF(COUNTIF(tbl_clean_sales[Invoice_ID],tbl_clean_sales[[#This Row],[Invoice_ID]])>1,"Duplicate","Unique") -> Duplicate | I51: Requires Source validation | J51: =IF(tbl_clean_sales[[#This Row],[Employee_ID]]="","Missing",IFERROR(IF(VLOOKUP(tbl_clean_sales[[#This Row],[Employee_ID]],'02_Employee_Master'!$A$1:$C$12,1,FALSE)=tbl_clean_sales[[#This Row],[Employee_ID]],"Valid","Invalid"),"Invalid")) -> Valid | K51: =IFERROR(VLOOKUP(tbl_clean_sales[[#This Row],[Employee_ID]],'02_Employee_Master'!$A$1:$C$12,2,FALSE),"Employee Name Missing") -> Divya R | L51: =IFERROR(VLOOKUP(tbl_clean_sales[[#This Row],[Employee_ID]],'02_Employee_Master'!$A$1:$C$12,3,FALSE),"Department Name Missing") -> Sales | M51: =IF('03_Clean_data'!D51="","Missing",IFERROR(IF(VLOOKUP(D51,'03_Product_Master'!$A$1:$D$14,1,FALSE)='03_Clean_data'!D51,"Valid","Invalid"),"Invalid")) -> Valid | N51: =IFERROR(VLOOKUP(tbl_clean_sales[[#This Row],[Product_ID]],'03_Product_Master'!$A$1:$D$14,2,FALSE),"Missing") -> Chocolate Bar | O51: =IFERROR(VLOOKUP(tbl_clean_sales[[#This Row],[Product_ID]],'03_Product_Master'!$A$1:$D$14,3,FALSE),"Missing") -> Snacks | P51: =IFERROR(VLOOKUP(tbl_clean_sales[[#This Row],[Product_ID]],'03_Product_Master'!$A$1:$D$14,4,FALSE),"Missing") -> 120 | Q51: =IF('03_Clean_data'!E51="","Missing",IFERROR(IF(VLOOKUP(E51,'04_Branch_Master'!$A$1:$C$7,1,FALSE)='03_Clean_data'!E51,"Valid","Invalid"),"Invalid")) -> Valid | R51: =IFERROR(VLOOKUP(tbl_clean_sales[[#This Row],[Branch_ID]],'04_Branch_Master'!$A$1:$C$7,2,FALSE),"Missing") -> Avinashi Road | S51: =IFERROR(VLOOKUP(tbl_clean_sales[[#This Row],[Branch_ID]],'04_Branch_Master'!$A$1:$C$7,3,FALSE),"Missing") -> North | T51: =C51&"|"&TEXT(tbl_clean_sales[[#This Row],[Date]],"yyyymm") -> E004|202605 | U51: =IFERROR(INDEX('05_Target_Master'!$A$1:$F$32,MATCH(tbl_clean_sales[[#This Row],[target key]],'05_Target_Master'!$F$1:$F$32,0),3),"Missing") -> 176700
A52: 46171 | B52: INV100051 | C52: E006 | D52: P002 | E52: B003 | F52: 10 | G52: 2464.52 | H52: =IF(COUNTIF(tbl_clean_sales[Invoice_ID],tbl_clean_sales[[#This Row],[Invoice_ID]])>1,"Duplicate","Unique") -> Unique | J52: =IF(tbl_clean_sales[[#This Row],[Employee_ID]]="","Missing",IFERROR(IF(VLOOKUP(tbl_clean_sales[[#This Row],[Employee_ID]],'02_Employee_Master'!$A$1:$C$12,1,FALSE)=tbl_clean_sales[[#This Row],[Employee_ID]],"Valid","Invalid"),"Invalid")) -> Valid | K52: =IFERROR(VLOOKUP(tbl_clean_sales[[#This Row],[Employee_ID]],'02_Employee_Master'!$A$1:$C$12,2,FALSE),"Employee Name Missing") -> Meena V | L52: =IFERROR(VLOOKUP(tbl_clean_sales[[#This Row],[Employee_ID]],'02_Employee_Master'!$A$1:$C$12,3,FALSE),"Department Name Missing") -> Sales | M52: =IF('03_Clean_data'!D52="","Missing",IFERROR(IF(VLOOKUP(D52,'03_Product_Master'!$A$1:$D$14,1,FALSE)='03_Clean_data'!D52,"Valid","Invalid"),"Invalid")) -> Valid | N52: =IFERROR(VLOOKUP(tbl_clean_sales[[#This Row],[Product_ID]],'03_Product_Master'!$A$1:$D$14,2,FALSE),"Missing") -> Green Tea | O52: =IFERROR(VLOOKUP(tbl_clean_sales[[#This Row],[Product_ID]],'03_Product_Master'!$A$1:$D$14,3,FALSE),"Missing") -> Beverages | P52: =IFERROR(VLOOKUP(tbl_clean_sales[[#This Row],[Product_ID]],'03_Product_Master'!$A$1:$D$14,4,FALSE),"Missing") -> 280 | Q52: =IF('03_Clean_data'!E52="","Missing",IFERROR(IF(VLOOKUP(E52,'04_Branch_Master'!$A$1:$C$7,1,FALSE)='03_Clean_data'!E52,"Valid","Invalid"),"Invalid")) -> Valid | R52: =IFERROR(VLOOKUP(tbl_clean_sales[[#This Row],[Branch_ID]],'04_Branch_Master'!$A$1:$C$7,2,FALSE),"Missing") -> Palladam | S52: =IFERROR(VLOOKUP(tbl_clean_sales[[#This Row],[Branch_ID]],'04_Branch_Master'!$A$1:$C$7,3,FALSE),"Missing") -> South | T52: =C52&"|"&TEXT(tbl_clean_sales[[#This Row],[Date]],"yyyymm") -> E006|202605 | U52: =IFERROR(INDEX('05_Target_Master'!$A$1:$F$32,MATCH(tbl_clean_sales[[#This Row],[target key]],'05_Target_Master'!$F$1:$F$32,0),3),"Missing") -> 141500
A53: 46125 | B53: INV100052 | C53: E002 | D53: P009 | E53: B001 | F53: 5 | G53: 1919.01 | H53: =IF(COUNTIF(tbl_clean_sales[Invoice_ID],tbl_clean_sales[[#This Row],[Invoice_ID]])>1,"Duplicate","Unique") -> Unique | J53: =IF(tbl_clean_sales[[#This Row],[Employee_ID]]="","Missing",IFERROR(IF(VLOOKUP(tbl_clean_sales[[#This Row],[Employee_ID]],'02_Employee_Master'!$A$1:$C$12,1,FALSE)=tbl_clean_sales[[#This Row],[Employee_ID]],"Valid","Invalid"),"Invalid")) -> Valid | K53: =IFERROR(VLOOKUP(tbl_clean_sales[[#This Row],[Employee_ID]],'02_Employee_Master'!$A$1:$C$12,2,FALSE),"Employee Name Missing") -> Priya S | L53: =IFERROR(VLOOKUP(tbl_clean_sales[[#This Row],[Employee_ID]],'02_Employee_Master'!$A$1:$C$12,3,FALSE),"Department Name Missing") -> Sales | M53: =IF('03_Clean_data'!D53="","Missing",IFERROR(IF(VLOOKUP(D53,'03_Product_Master'!$A$1:$D$14,1,FALSE)='03_Clean_data'!D53,"Valid","Invalid"),"Invalid")) -> Valid | N53: =IFERROR(VLOOKUP(tbl_clean_sales[[#This Row],[Product_ID]],'03_Product_Master'!$A$1:$D$14,2,FALSE),"Missing") -> Body Lotion | O53: =IFERROR(VLOOKUP(tbl_clean_sales[[#This Row],[Product_ID]],'03_Product_Master'!$A$1:$D$14,3,FALSE),"Missing") -> Personal Care | P53: =IFERROR(VLOOKUP(tbl_clean_sales[[#This Row],[Product_ID]],'03_Product_Master'!$A$1:$D$14,4,FALSE),"Missing") -> 390 | Q53: =IF('03_Clean_data'!E53="","Missing",IFERROR(IF(VLOOKUP(E53,'04_Branch_Master'!$A$1:$C$7,1,FALSE)='03_Clean_data'!E53,"Valid","Invalid"),"Invalid")) -> Valid | R53: =IFERROR(VLOOKUP(tbl_clean_sales[[#This Row],[Branch_ID]],'04_Branch_Master'!$A$1:$C$7,2,FALSE),"Missing") -> Tirupur Central | S53: =IFERROR(VLOOKUP(tbl_clean_sales[[#This Row],[Branch_ID]],'04_Branch_Master'!$A$1:$C$7,3,FALSE),"Missing") -> North | T53: =C53&"|"&TEXT(tbl_clean_sales[[#This Row],[Date]],"yyyymm") -> E002|202604 | U53: =IFERROR(INDEX('05_Target_Master'!$A$1:$F$32,MATCH(tbl_clean_sales[[#This Row],[target key]],'05_Target_Master'!$F$1:$F$32,0),3),"Missing") -> 122300
A54: 46157 | B54: INV100053 | C54: E002 | D54: P004 | E54: B001 | F54: 3 | G54: 454.76 | H54: =IF(COUNTIF(tbl_clean_sales[Invoice_ID],tbl_clean_sales[[#This Row],[Invoice_ID]])>1,"Duplicate","Unique") -> Unique | J54: =IF(tbl_clean_sales[[#This Row],[Employee_ID]]="","Missing",IFERROR(IF(VLOOKUP(tbl_clean_sales[[#This Row],[Employee_ID]],'02_Employee_Master'!$A$1:$C$12,1,FALSE)=tbl_clean_sales[[#This Row],[Employee_ID]],"Valid","Invalid"),"Invalid")) -> Valid | K54: =IFERROR(VLOOKUP(tbl_clean_sales[[#This Row],[Employee_ID]],'02_Employee_Master'!$A$1:$C$12,2,FALSE),"Employee Name Missing") -> Priya S | L54: =IFERROR(VLOOKUP(tbl_clean_sales[[#This Row],[Employee_ID]],'02_Employee_Master'!$A$1:$C$12,3,FALSE),"Department Name Missing") -> Sales | M54: =IF('03_Clean_data'!D54="","Missing",IFERROR(IF(VLOOKUP(D54,'03_Product_Master'!$A$1:$D$14,1,FALSE)='03_Clean_data'!D54,"Valid","Invalid"),"Invalid")) -> Valid | N54: =IFERROR(VLOOKUP(tbl_clean_sales[[#This Row],[Product_ID]],'03_Product_Master'!$A$1:$D$14,2,FALSE),"Missing") -> Cookies Pack | O54: =IFERROR(VLOOKUP(tbl_clean_sales[[#This Row],[Product_ID]],'03_Product_Master'!$A$1:$D$14,3,FALSE),"Missing") -> Snacks | P54: =IFERROR(VLOOKUP(tbl_clean_sales[[#This Row],[Product_ID]],'03_Product_Master'!$A$1:$D$14,4,FALSE),"Missing") -> 160 | Q54: =IF('03_Clean_data'!E54="","Missing",IFERROR(IF(VLOOKUP(E54,'04_Branch_Master'!$A$1:$C$7,1,FALSE)='03_Clean_data'!E54,"Valid","Invalid"),"Invalid")) -> Valid | R54: =IFERROR(VLOOKUP(tbl_clean_sales[[#This Row],[Branch_ID]],'04_Branch_Master'!$A$1:$C$7,2,FALSE),"Missing") -> Tirupur Central | S54: =IFERROR(VLOOKUP(tbl_clean_sales[[#This Row],[Branch_ID]],'04_Branch_Master'!$A$1:$C$7,3,FALSE),"Missing") -> North | T54: =C54&"|"&TEXT(tbl_clean_sales[[#This Row],[Date]],"yyyymm") -> E002|202605 | U54: =IFERROR(INDEX('05_Target_Master'!$A$1:$F$32,MATCH(tbl_clean_sales[[#This Row],[target key]],'05_Target_Master'!$F$1:$F$32,0),3),"Missing") -> 132100
A55: 46182 | B55: INV100054 | C55: E005 | D55: P010 | E55: B005 | F55: 1 | G55: 174.77 | H55: =IF(COUNTIF(tbl_clean_sales[Invoice_ID],tbl_clean_sales[[#This Row],[Invoice_ID]])>1,"Duplicate","Unique") -> Unique | J55: =IF(tbl_clean_sales[[#This Row],[Employee_ID]]="","Missing",IFERROR(IF(VLOOKUP(tbl_clean_sales[[#This Row],[Employee_ID]],'02_Employee_Master'!$A$1:$C$12,1,FALSE)=tbl_clean_sales[[#This Row],[Employee_ID]],"Valid","Invalid"),"Invalid")) -> Valid | K55: =IFERROR(VLOOKUP(tbl_clean_sales[[#This Row],[Employee_ID]],'02_Employee_Master'!$A$1:$C$12,2,FALSE),"Employee Name Missing") -> Karthik P | L55: =IFERROR(VLOOKUP(tbl_clean_sales[[#This Row],[Employee_ID]],'02_Employee_Master'!$A$1:$C$12,3,FALSE),"Department Name Missing") -> Sales | M55: =IF('03_Clean_data'!D55="","Missing",IFERROR(IF(VLOOKUP(D55,'03_Product_Master'!$A$1:$D$14,1,FALSE)='03_Clean_data'!D55,"Valid","Invalid"),"Invalid")) -> Valid | N55: =IFERROR(VLOOKUP(tbl_clean_sales[[#This Row],[Product_ID]],'03_Product_Master'!$A$1:$D$14,2,FALSE),"Missing") -> Dish Wash | O55: =IFERROR(VLOOKUP(tbl_clean_sales[[#This Row],[Product_ID]],'03_Product_Master'!$A$1:$D$14,3,FALSE),"Missing") -> Home Care | P55: =IFERROR(VLOOKUP(tbl_clean_sales[[#This Row],[Product_ID]],'03_Product_Master'!$A$1:$D$14,4,FALSE),"Missing") -> 190 | Q55: =IF('03_Clean_data'!E55="","Missing",IFERROR(IF(VLOOKUP(E55,'04_Branch_Master'!$A$1:$C$7,1,FALSE)='03_Clean_data'!E55,"Valid","Invalid"),"Invalid")) -> Valid | R55: =IFERROR(VLOOKUP(tbl_clean_sales[[#This Row],[Branch_ID]],'04_Branch_Master'!$A$1:$C$7,2,FALSE),"Missing") -> Dharapuram | S55: =IFERROR(VLOOKUP(tbl_clean_sales[[#This Row],[Branch_ID]],'04_Branch_Master'!$A$1:$C$7,3,FALSE),"Missing") -> South | T55: =C55&"|"&TEXT(tbl_clean_sales[[#This Row],[Date]],"yyyymm") -> E005|202606 | U55: =IFERROR(INDEX('05_Target_Master'!$A$1:$F$32,MATCH(tbl_clean_sales[[#This Row],[target key]],'05_Target_Master'!$F$1:$F$32,0),3),"Missing") -> 127700
A56: 46183 | B56: INV100055 | C56: E005 | D56: P011 | E56: B003 | F56: 3 | G56: 987.63 | H56: =IF(COUNTIF(tbl_clean_sales[Invoice_ID],tbl_clean_sales[[#This Row],[Invoice_ID]])>1,"Duplicate","Unique") -> Unique | J56: =IF(tbl_clean_sales[[#This Row],[Employee_ID]]="","Missing",IFERROR(IF(VLOOKUP(tbl_clean_sales[[#This Row],[Employee_ID]],'02_Employee_Master'!$A$1:$C$12,1,FALSE)=tbl_clean_sales[[#This Row],[Employee_ID]],"Valid","Invalid"),"Invalid")) -> Valid | K56: =IFERROR(VLOOKUP(tbl_clean_sales[[#This Row],[Employee_ID]],'02_Employee_Master'!$A$1:$C$12,2,FALSE),"Employee Name Missing") -> Karthik P | L56: =IFERROR(VLOOKUP(tbl_clean_sales[[#This Row],[Employee_ID]],'02_Employee_Master'!$A$1:$C$12,3,FALSE),"Department Name Missing") -> Sales | M56: =IF('03_Clean_data'!D56="","Missing",IFERROR(IF(VLOOKUP(D56,'03_Product_Master'!$A$1:$D$14,1,FALSE)='03_Clean_data'!D56,"Valid","Invalid"),"Invalid")) -> Valid | N56: =IFERROR(VLOOKUP(tbl_clean_sales[[#This Row],[Product_ID]],'03_Product_Master'!$A$1:$D$14,2,FALSE),"Missing") -> Laundry Liquid | O56: =IFERROR(VLOOKUP(tbl_clean_sales[[#This Row],[Product_ID]],'03_Product_Master'!$A$1:$D$14,3,FALSE),"Missing") -> Home Care | P56: =IFERROR(VLOOKUP(tbl_clean_sales[[#This Row],[Product_ID]],'03_Product_Master'!$A$1:$D$14,4,FALSE),"Missing") -> 340 | Q56: =IF('03_Clean_data'!E56="","Missing",IFERROR(IF(VLOOKUP(E56,'04_Branch_Master'!$A$1:$C$7,1,FALSE)='03_Clean_data'!E56,"Valid","Invalid"),"Invalid")) -> Valid | R56: =IFERROR(VLOOKUP(tbl_clean_sales[[#This Row],[Branch_ID]],'04_Branch_Master'!$A$1:$C$7,2,FALSE),"Missing") -> Palladam | S56: =IFERROR(VLOOKUP(tbl_clean_sales[[#This Row],[Branch_ID]],'04_Branch_Master'!$A$1:$C$7,3,FALSE),"Missing") -> South | T56: =C56&"|"&TEXT(tbl_clean_sales[[#This Row],[Date]],"yyyymm") -> E005|202606 | U56: =IFERROR(INDEX('05_Target_Master'!$A$1:$F$32,MATCH(tbl_clean_sales[[#This Row],[target key]],'05_Target_Master'!$F$1:$F$32,0),3),"Missing") -> 127700
A57: 46126 | B57: INV100056 | C57: E009 | D57: P003 | E57: B005 | F57: 10 | G57: 3411.54 | H57: =IF(COUNTIF(tbl_clean_sales[Invoice_ID],tbl_clean_sales[[#This Row],[Invoice_ID]])>1,"Duplicate","Unique") -> Unique | J57: =IF(tbl_clean_sales[[#This Row],[Employee_ID]]="","Missing",IFERROR(IF(VLOOKUP(tbl_clean_sales[[#This Row],[Employee_ID]],'02_Employee_Master'!$A$1:$C$12,1,FALSE)=tbl_clean_sales[[#This Row],[Employee_ID]],"Valid","Invalid"),"Invalid")) -> Valid | K57: =IFERROR(VLOOKUP(tbl_clean_sales[[#This Row],[Employee_ID]],'02_Employee_Master'!$A$1:$C$12,2,FALSE),"Employee Name Missing") -> Vignesh R | L57: =IFERROR(VLOOKUP(tbl_clean_sales[[#This Row],[Employee_ID]],'02_Employee_Master'!$A$1:$C$12,3,FALSE),"Department Name Missing") -> Sales | M57: =IF('03_Clean_data'!D57="","Missing",IFERROR(IF(VLOOKUP(D57,'03_Product_Master'!$A$1:$D$14,1,FALSE)='03_Clean_data'!D57,"Valid","Invalid"),"Invalid")) -> Valid | N57: =IFERROR(VLOOKUP(tbl_clean_sales[[#This Row],[Product_ID]],'03_Product_Master'!$A$1:$D$14,2,FALSE),"Missing") -> Instant Coffee | O57: =IFERROR(VLOOKUP(tbl_clean_sales[[#This Row],[Product_ID]],'03_Product_Master'!$A$1:$D$14,3,FALSE),"Missing") -> Beverages | P57: =IFERROR(VLOOKUP(tbl_clean_sales[[#This Row],[Product_ID]],'03_Product_Master'!$A$1:$D$14,4,FALSE),"Missing") -> 350 | Q57: =IF('03_Clean_data'!E57="","Missing",IFERROR(IF(VLOOKUP(E57,'04_Branch_Master'!$A$1:$C$7,1,FALSE)='03_Clean_data'!E57,"Valid","Invalid"),"Invalid")) -> Valid | R57: =IFERROR(VLOOKUP(tbl_clean_sales[[#This Row],[Branch_ID]],'04_Branch_Master'!$A$1:$C$7,2,FALSE),"Missing") -> Dharapuram | S57: =IFERROR(VLOOKUP(tbl_clean_sales[[#This Row],[Branch_ID]],'04_Branch_Master'!$A$1:$C$7,3,FALSE),"Missing") -> South | T57: =C57&"|"&TEXT(tbl_clean_sales[[#This Row],[Date]],"yyyymm") -> E009|202604 | U57: =IFERROR(INDEX('05_Target_Master'!$A$1:$F$32,MATCH(tbl_clean_sales[[#This Row],[target key]],'05_Target_Master'!$F$1:$F$32,0),3),"Missing") -> 163300
A58: 46156 | B58: INV100057 | C58: E004 | D58: P011 | E58: B002 | F58: 5 | G58: 1596.9 | H58: =IF(COUNTIF(tbl_clean_sales[Invoice_ID],tbl_clean_sales[[#This Row],[Invoice_ID]])>1,"Duplicate","Unique") -> Unique | J58: =IF(tbl_clean_sales[[#This Row],[Employee_ID]]="","Missing",IFERROR(IF(VLOOKUP(tbl_clean_sales[[#This Row],[Employee_ID]],'02_Employee_Master'!$A$1:$C$12,1,FALSE)=tbl_clean_sales[[#This Row],[Employee_ID]],"Valid","Invalid"),"Invalid")) -> Valid | K58: =IFERROR(VLOOKUP(tbl_clean_sales[[#This Row],[Employee_ID]],'02_Employee_Master'!$A$1:$C$12,2,FALSE),"Employee Name Missing") -> Divya R | L58: =IFERROR(VLOOKUP(tbl_clean_sales[[#This Row],[Employee_ID]],'02_Employee_Master'!$A$1:$C$12,3,FALSE),"Department Name Missing") -> Sales | M58: =IF('03_Clean_data'!D58="","Missing",IFERROR(IF(VLOOKUP(D58,'03_Product_Master'!$A$1:$D$14,1,FALSE)='03_Clean_data'!D58,"Valid","Invalid"),"Invalid")) -> Valid | N58: =IFERROR(VLOOKUP(tbl_clean_sales[[#This Row],[Product_ID]],'03_Product_Master'!$A$1:$D$14,2,FALSE),"Missing") -> Laundry Liquid | O58: =IFERROR(VLOOKUP(tbl_clean_sales[[#This Row],[Product_ID]],'03_Product_Master'!$A$1:$D$14,3,FALSE),"Missing") -> Home Care | P58: =IFERROR(VLOOKUP(tbl_clean_sales[[#This Row],[Product_ID]],'03_Product_Master'!$A$1:$D$14,4,FALSE),"Missing") -> 340 | Q58: =IF('03_Clean_data'!E58="","Missing",IFERROR(IF(VLOOKUP(E58,'04_Branch_Master'!$A$1:$C$7,1,FALSE)='03_Clean_data'!E58,"Valid","Invalid"),"Invalid")) -> Valid | R58: =IFERROR(VLOOKUP(tbl_clean_sales[[#This Row],[Branch_ID]],'04_Branch_Master'!$A$1:$C$7,2,FALSE),"Missing") -> Avinashi Road | S58: =IFERROR(VLOOKUP(tbl_clean_sales[[#This Row],[Branch_ID]],'04_Branch_Master'!$A$1:$C$7,3,FALSE),"Missing") -> North | T58: =C58&"|"&TEXT(tbl_clean_sales[[#This Row],[Date]],"yyyymm") -> E004|202605 | U58: =IFERROR(INDEX('05_Target_Master'!$A$1:$F$32,MATCH(tbl_clean_sales[[#This Row],[target key]],'05_Target_Master'!$F$1:$F$32,0),3),"Missing") -> 176700
A59: 46145 | B59: INV100058 | C59: E001 | D59: P002 | E59: B001 | F59: 5 | G59: 1392.59 | H59: =IF(COUNTIF(tbl_clean_sales[Invoice_ID],tbl_clean_sales[[#This Row],[Invoice_ID]])>1,"Duplicate","Unique") -> Unique | J59: =IF(tbl_clean_sales[[#This Row],[Employee_ID]]="","Missing",IFERROR(IF(VLOOKUP(tbl_clean_sales[[#This Row],[Employee_ID]],'02_Employee_Master'!$A$1:$C$12,1,FALSE)=tbl_clean_sales[[#This Row],[Employee_ID]],"Valid","Invalid"),"Invalid")) -> Valid | K59: =IFERROR(VLOOKUP(tbl_clean_sales[[#This Row],[Employee_ID]],'02_Employee_Master'!$A$1:$C$12,2,FALSE),"Employee Name Missing") -> Arun Kumar | L59: =IFERROR(VLOOKUP(tbl_clean_sales[[#This Row],[Employee_ID]],'02_Employee_Master'!$A$1:$C$12,3,FALSE),"Department Name Missing") -> Sales | M59: =IF('03_Clean_data'!D59="","Missing",IFERROR(IF(VLOOKUP(D59,'03_Product_Master'!$A$1:$D$14,1,FALSE)='03_Clean_data'!D59,"Valid","Invalid"),"Invalid")) -> Valid | N59: =IFERROR(VLOOKUP(tbl_clean_sales[[#This Row],[Product_ID]],'03_Product_Master'!$A$1:$D$14,2,FALSE),"Missing") -> Green Tea | O59: =IFERROR(VLOOKUP(tbl_clean_sales[[#This Row],[Product_ID]],'03_Product_Master'!$A$1:$D$14,3,FALSE),"Missing") -> Beverages | P59: =IFERROR(VLOOKUP(tbl_clean_sales[[#This Row],[Product_ID]],'03_Product_Master'!$A$1:$D$14,4,FALSE),"Missing") -> 280 | Q59: =IF('03_Clean_data'!E59="","Missing",IFERROR(IF(VLOOKUP(E59,'04_Branch_Master'!$A$1:$C$7,1,FALSE)='03_Clean_data'!E59,"Valid","Invalid"),"Invalid")) -> Valid | R59: =IFERROR(VLOOKUP(tbl_clean_sales[[#This Row],[Branch_ID]],'04_Branch_Master'!$A$1:$C$7,2,FALSE),"Missing") -> Tirupur Central | S59: =IFERROR(VLOOKUP(tbl_clean_sales[[#This Row],[Branch_ID]],'04_Branch_Master'!$A$1:$C$7,3,FALSE),"Missing") -> North | T59: =C59&"|"&TEXT(tbl_clean_sales[[#This Row],[Date]],"yyyymm") -> E001|202605 | U59: =IFERROR(INDEX('05_Target_Master'!$A$1:$F$32,MATCH(tbl_clean_sales[[#This Row],[target key]],'05_Target_Master'!$F$1:$F$32,0),3),"Missing") -> 169500
A60: 46155 | B60: INV100059 | C60: E003 | D60: P011 | E60: B002 | F60: 12 | G60: 3863.68 | H60: =IF(COUNTIF(tbl_clean_sales[Invoice_ID],tbl_clean_sales[[#This Row],[Invoice_ID]])>1,"Duplicate","Unique") -> Unique | J60: =IF(tbl_clean_sales[[#This Row],[Employee_ID]]="","Missing",IFERROR(IF(VLOOKUP(tbl_clean_sales[[#This Row],[Employee_ID]],'02_Employee_Master'!$A$1:$C$12,1,FALSE)=tbl_clean_sales[[#This Row],[Employee_ID]],"Valid","Invalid"),"Invalid")) -> Valid | K60: =IFERROR(VLOOKUP(tbl_clean_sales[[#This Row],[Employee_ID]],'02_Employee_Master'!$A$1:$C$12,2,FALSE),"Employee Name Missing") -> Rahul M | L60: =IFERROR(VLOOKUP(tbl_clean_sales[[#This Row],[Employee_ID]],'02_Employee_Master'!$A$1:$C$12,3,FALSE),"Department Name Missing") -> Sales | M60: =IF('03_Clean_data'!D60="","Missing",IFERROR(IF(VLOOKUP(D60,'03_Product_Master'!$A$1:$D$14,1,FALSE)='03_Clean_data'!D60,"Valid","Invalid"),"Invalid")) -> Valid | N60: =IFERROR(VLOOKUP(tbl_clean_sales[[#This Row],[Product_ID]],'03_Product_Master'!$A$1:$D$14,2,FALSE),"Missing") -> Laundry Liquid | O60: =IFERROR(VLOOKUP(tbl_clean_sales[[#This Row],[Product_ID]],'03_Product_Master'!$A$1:$D$14,3,FALSE),"Missing") -> Home Care | P60: =IFERROR(VLOOKUP(tbl_clean_sales[[#This Row],[Product_ID]],'03_Product_Master'!$A$1:$D$14,4,FALSE),"Missing") -> 340 | Q60: =IF('03_Clean_data'!E60="","Missing",IFERROR(IF(VLOOKUP(E60,'04_Branch_Master'!$A$1:$C$7,1,FALSE)='03_Clean_data'!E60,"Valid","Invalid"),"Invalid")) -> Valid | R60: =IFERROR(VLOOKUP(tbl_clean_sales[[#This Row],[Branch_ID]],'04_Branch_Master'!$A$1:$C$7,2,FALSE),"Missing") -> Avinashi Road | S60: =IFERROR(VLOOKUP(tbl_clean_sales[[#This Row],[Branch_ID]],'04_Branch_Master'!$A$1:$C$7,3,FALSE),"Missing") -> North | T60: =C60&"|"&TEXT(tbl_clean_sales[[#This Row],[Date]],"yyyymm") -> E003|202605 | U60: =IFERROR(INDEX('05_Target_Master'!$A$1:$F$32,MATCH(tbl_clean_sales[[#This Row],[target key]],'05_Target_Master'!$F$1:$F$32,0),3),"Missing") -> 126000
A61: 46203 | B61: INV100060 | C61: E007 | D61: P009 | E61: B004 | F61: 2 | G61: 691.54 | H61: =IF(COUNTIF(tbl_clean_sales[Invoice_ID],tbl_clean_sales[[#This Row],[Invoice_ID]])>1,"Duplicate","Unique") -> Unique | J61: =IF(tbl_clean_sales[[#This Row],[Employee_ID]]="","Missing",IFERROR(IF(VLOOKUP(tbl_clean_sales[[#This Row],[Employee_ID]],'02_Employee_Master'!$A$1:$C$12,1,FALSE)=tbl_clean_sales[[#This Row],[Employee_ID]],"Valid","Invalid"),"Invalid")) -> Valid | K61: =IFERROR(VLOOKUP(tbl_clean_sales[[#This Row],[Employee_ID]],'02_Employee_Master'!$A$1:$C$12,2,FALSE),"Employee Name Missing") -> Suresh B | L61: =IFERROR(VLOOKUP(tbl_clean_sales[[#This Row],[Employee_ID]],'02_Employee_Master'!$A$1:$C$12,3,FALSE),"Department Name Missing") -> Sales | M61: =IF('03_Clean_data'!D61="","Missing",IFERROR(IF(VLOOKUP(D61,'03_Product_Master'!$A$1:$D$14,1,FALSE)='03_Clean_data'!D61,"Valid","Invalid"),"Invalid")) -> Valid | N61: =IFERROR(VLOOKUP(tbl_clean_sales[[#This Row],[Product_ID]],'03_Product_Master'!$A$1:$D$14,2,FALSE),"Missing") -> Body Lotion | O61: =IFERROR(VLOOKUP(tbl_clean_sales[[#This Row],[Product_ID]],'03_Product_Master'!$A$1:$D$14,3,FALSE),"Missing") -> Personal Care | P61: =IFERROR(VLOOKUP(tbl_clean_sales[[#This Row],[Product_ID]],'03_Product_Master'!$A$1:$D$14,4,FALSE),"Missing") -> 390 | Q61: =IF('03_Clean_data'!E61="","Missing",IFERROR(IF(VLOOKUP(E61,'04_Branch_Master'!$A$1:$C$7,1,FALSE)='03_Clean_data'!E61,"Valid","Invalid"),"Invalid")) -> Valid | R61: =IFERROR(VLOOKUP(tbl_clean_sales[[#This Row],[Branch_ID]],'04_Branch_Master'!$A$1:$C$7,2,FALSE),"Missing") -> Kangeyam | S61: =IFERROR(VLOOKUP(tbl_clean_sales[[#This Row],[Branch_ID]],'04_Branch_Master'!$A$1:$C$7,3,FALSE),"Missing") -> East | T61: =C61&"|"&TEXT(tbl_clean_sales[[#This Row],[Date]],"yyyymm") -> E007|202606 | U61: =IFERROR(INDEX('05_Target_Master'!$A$1:$F$32,MATCH(tbl_clean_sales[[#This Row],[target key]],'05_Target_Master'!$F$1:$F$32,0),3),"Missing") -> 124400
